<?xml version="1.0" ?>
<mujoco model="spirob_reversed">
  <option timestep="0.002" gravity="0 0 -9.81"/>
  <asset>
    <texture name="grid" type="2d" builtin="checker" rgb1=".1 .2 .3" rgb2=".2 .3 .4" width="300" height="300"/>
    <material name="grid" texture="grid" texrepeat="1 1" reflectance="0.2"/>
  </asset>
  <default>
    <geom friction="0.5" solimp="0.9 0.95 0.001" solref="0.02 1"/>
    <joint type="hinge" axis="0 0 1" stiffness="2.0" damping="0.2" limited="true" range="-30 30"/>
  </default>
  <worldbody>
    <geom name="floor" type="plane" size="2 2 0.1" material="grid"/>
    <light diffuse=".5 .5 .5" pos="0 0 3" dir="0 0 -1"/>
    <body name="base" pos="0 0 0.2">
      <body name="seg_0" pos="0 0 0" euler="0 0 0.0">
        <joint name="j_0"/>
        <geom type="box" size="0.023576399697969007 0.028291679637562808 0.005" pos="0.023576399697969007 0 0" rgba="0.2 0.6 0.8 1"/>
        <site name="s1_0" pos="0.023576399697969007 0.03395001556507537 0" size="0.002" rgba="1 1 0 1"/>
        <site name="s2_0" pos="0.023576399697969007 -0.03395001556507537 0" size="0.002" rgba="1 1 0 1"/>
        <body name="seg_1" pos="0.047152799395938014 0 0" euler="0 0 -11.250000000000044">
          <joint name="j_1"/>
          <geom type="box" size="0.022668499889541775 0.02720219986745013 0.005" pos="0.022668499889541775 0 0" rgba="0.2 0.6 0.8 1"/>
          <site name="s1_1" pos="0.022668499889541775 0.03264263984094015 0" size="0.002" rgba="1 1 0 1"/>
          <site name="s2_1" pos="0.022668499889541775 -0.03264263984094015 0" size="0.002" rgba="1 1 0 1"/>
          <body name="seg_2" pos="0.04533699977908355 0 0" euler="0 0 -11.249999999999908">
            <joint name="j_2"/>
            <geom type="box" size="0.0217955622497535 0.0261546746997042 0.005" pos="0.0217955622497535 0 0" rgba="0.2 0.6 0.8 1"/>
            <site name="s1_2" pos="0.0217955622497535 0.03138560963964504 0" size="0.002" rgba="1 1 0 1"/>
            <site name="s2_2" pos="0.0217955622497535 -0.03138560963964504 0" size="0.002" rgba="1 1 0 1"/>
            <body name="seg_3" pos="0.043591124499507 0 0" euler="0 0 -11.250000000000146">
              <joint name="j_3"/>
              <geom type="box" size="0.020956240426039375 0.02514748851124725 0.005" pos="0.020956240426039375 0 0" rgba="0.2 0.6 0.8 1"/>
              <site name="s1_3" pos="0.020956240426039375 0.030176986213496695 0" size="0.002" rgba="1 1 0 1"/>
              <site name="s2_3" pos="0.020956240426039375 -0.030176986213496695 0" size="0.002" rgba="1 1 0 1"/>
              <body name="seg_4" pos="0.04191248085207875 0 0" euler="0 0 -11.249999999999917">
                <joint name="j_4"/>
                <geom type="box" size="0.02014923991230974 0.02417908789477169 0.005" pos="0.02014923991230974 0 0" rgba="0.2 0.6 0.8 1"/>
                <site name="s1_4" pos="0.02014923991230974 0.029014905473726024 0" size="0.002" rgba="1 1 0 1"/>
                <site name="s2_4" pos="0.02014923991230974 -0.029014905473726024 0" size="0.002" rgba="1 1 0 1"/>
                <body name="seg_5" pos="0.04029847982461948 0 0" euler="0 0 -11.249999999999961">
                  <joint name="j_5"/>
                  <geom type="box" size="0.019373316052403416 0.0232479792628841 0.005" pos="0.019373316052403416 0 0" rgba="0.2 0.6 0.8 1"/>
                  <site name="s1_5" pos="0.019373316052403416 0.027897575115460916 0" size="0.002" rgba="1 1 0 1"/>
                  <site name="s2_5" pos="0.019373316052403416 -0.027897575115460916 0" size="0.002" rgba="1 1 0 1"/>
                  <body name="seg_6" pos="0.03874663210480683 0 0" euler="0 0 -11.250000000000012">
                    <joint name="j_6"/>
                    <geom type="box" size="0.018627272120424667 0.0223527265445096 0.005" pos="0.018627272120424667 0 0" rgba="0.2 0.6 0.8 1"/>
                    <site name="s1_6" pos="0.018627272120424667 0.02682327185341152 0" size="0.002" rgba="1 1 0 1"/>
                    <site name="s2_6" pos="0.018627272120424667 -0.02682327185341152 0" size="0.002" rgba="1 1 0 1"/>
                    <body name="seg_7" pos="0.037254544240849334 0 0" euler="0 0 -11.250000000000101">
                      <joint name="j_7"/>
                      <geom type="box" size="0.017909957475003548 0.021491948970004258 0.005" pos="0.017909957475003548 0 0" rgba="0.2 0.6 0.8 1"/>
                      <site name="s1_7" pos="0.017909957475003548 0.02579033876400511 0" size="0.002" rgba="1 1 0 1"/>
                      <site name="s2_7" pos="0.017909957475003548 -0.02579033876400511 0" size="0.002" rgba="1 1 0 1"/>
                      <body name="seg_8" pos="0.035819914950007095 0 0" euler="0 0 -11.249999999999847">
                        <joint name="j_8"/>
                        <geom type="box" size="0.017220265784635036 0.02066431894156204 0.005" pos="0.017220265784635036 0 0" rgba="0.2 0.6 0.8 1"/>
                        <site name="s1_8" pos="0.017220265784635036 0.02479718272987445 0" size="0.002" rgba="1 1 0 1"/>
                        <site name="s2_8" pos="0.017220265784635036 -0.02479718272987445 0" size="0.002" rgba="1 1 0 1"/>
                        <body name="seg_9" pos="0.03444053156927007 0 0" euler="0 0 -11.250000000000101">
                          <joint name="j_9"/>
                          <geom type="box" size="0.016557133321357238 0.019868559985628684 0.005" pos="0.016557133321357238 0 0" rgba="0.2 0.6 0.8 1"/>
                          <site name="s1_9" pos="0.016557133321357238 0.02384227198275442 0" size="0.002" rgba="1 1 0 1"/>
                          <site name="s2_9" pos="0.016557133321357238 -0.02384227198275442 0" size="0.002" rgba="1 1 0 1"/>
                          <body name="seg_10" pos="0.033114266642714475 0 0" euler="0 0 -11.250000000000037">
                            <joint name="j_10"/>
                            <geom type="box" size="0.015919537320138233 0.01910344478416588 0.005" pos="0.015919537320138233 0 0" rgba="0.2 0.6 0.8 1"/>
                            <site name="s1_10" pos="0.015919537320138233 0.022924133740999053 0" size="0.002" rgba="1 1 0 1"/>
                            <site name="s2_10" pos="0.015919537320138233 -0.022924133740999053 0" size="0.002" rgba="1 1 0 1"/>
                            <body name="seg_11" pos="0.031839074640276466 0 0" euler="0 0 -11.249999999999936">
                              <joint name="j_11"/>
                              <geom type="box" size="0.015306494401441578 0.018367793281729893 0.005" pos="0.015306494401441578 0 0" rgba="0.2 0.6 0.8 1"/>
                              <site name="s1_11" pos="0.015306494401441578 0.02204135193807587 0" size="0.002" rgba="1 1 0 1"/>
                              <site name="s2_11" pos="0.015306494401441578 -0.02204135193807587 0" size="0.002" rgba="1 1 0 1"/>
                              <body name="seg_12" pos="0.030612988802883156 0 0" euler="0 0 -11.249999999999988">
                                <joint name="j_12"/>
                                <geom type="box" size="0.014717059054535802 0.01766047086544296 0.005" pos="0.014717059054535802 0 0" rgba="0.2 0.6 0.8 1"/>
                                <site name="s1_12" pos="0.014717059054535802 0.021192565038531553 0" size="0.002" rgba="1 1 0 1"/>
                                <site name="s2_12" pos="0.014717059054535802 -0.021192565038531553 0" size="0.002" rgba="1 1 0 1"/>
                                <body name="seg_13" pos="0.029434118109071605 0 0" euler="0 0 -11.249999999999936">
                                  <joint name="j_13"/>
                                  <geom type="box" size="0.014150322179211373 0.016980386615053647 0.005" pos="0.014150322179211373 0 0" rgba="0.2 0.6 0.8 1"/>
                                  <site name="s1_13" pos="0.014150322179211373 0.020376463938064377 0" size="0.002" rgba="1 1 0 1"/>
                                  <site name="s2_13" pos="0.014150322179211373 -0.020376463938064377 0" size="0.002" rgba="1 1 0 1"/>
                                  <body name="seg_14" pos="0.028300644358422746 0 0" euler="0 0 -11.250000000000064">
                                    <joint name="j_14"/>
                                    <geom type="box" size="0.013605409683653594 0.016326491620384312 0.005" pos="0.013605409683653594 0 0" rgba="0.2 0.6 0.8 1"/>
                                    <site name="s1_14" pos="0.013605409683653594 0.019591789944461174 0" size="0.002" rgba="1 1 0 1"/>
                                    <site name="s2_14" pos="0.013605409683653594 -0.019591789944461174 0" size="0.002" rgba="1 1 0 1"/>
                                    <body name="seg_15" pos="0.02721081936730719 0 0" euler="0 0 348.74999999999994">
                                      <joint name="j_15"/>
                                      <geom type="box" size="0.013081481136309395 0.015697777363571273 0.005" pos="0.013081481136309395 0 0" rgba="0.2 0.6 0.8 1"/>
                                      <site name="s1_15" pos="0.013081481136309395 0.01883733283628553 0" size="0.002" rgba="1 1 0 1"/>
                                      <site name="s2_15" pos="0.013081481136309395 -0.01883733283628553 0" size="0.002" rgba="1 1 0 1"/>
                                      <body name="seg_16" pos="0.02616296227261879 0 0" euler="0 0 -11.249999999999911">
                                        <joint name="j_16"/>
                                        <geom type="box" size="0.012577728469670348 0.015093274163604417 0.005" pos="0.012577728469670348 0 0" rgba="0.2 0.6 0.8 1"/>
                                        <site name="s1_16" pos="0.012577728469670348 0.0181119289963253 0" size="0.002" rgba="1 1 0 1"/>
                                        <site name="s2_16" pos="0.012577728469670348 -0.0181119289963253 0" size="0.002" rgba="1 1 0 1"/>
                                        <body name="seg_17" pos="0.025155456939340695 0 0" euler="0 0 -11.249999999999988">
                                          <joint name="j_17"/>
                                          <geom type="box" size="0.012093374733970527 0.014512049680764631 0.005" pos="0.012093374733970527 0 0" rgba="0.2 0.6 0.8 1"/>
                                          <site name="s1_17" pos="0.012093374733970527 0.017414459616917555 0" size="0.002" rgba="1 1 0 1"/>
                                          <site name="s2_17" pos="0.012093374733970527 -0.017414459616917555 0" size="0.002" rgba="1 1 0 1"/>
                                          <body name="seg_18" pos="0.024186749467941054 0 0" euler="0 0 -11.250000000000012">
                                            <joint name="j_18"/>
                                            <geom type="box" size="0.011627672898878307 0.013953207478653968 0.005" pos="0.011627672898878307 0 0" rgba="0.2 0.6 0.8 1"/>
                                            <site name="s1_18" pos="0.011627672898878307 0.01674384897438476 0" size="0.002" rgba="1 1 0 1"/>
                                            <site name="s2_18" pos="0.011627672898878307 -0.01674384897438476 0" size="0.002" rgba="1 1 0 1"/>
                                            <body name="seg_19" pos="0.023255345797756614 0 0" euler="0 0 -11.249999999999988">
                                              <joint name="j_19"/>
                                              <geom type="box" size="0.011179904701333954 0.013415885641600744 0.005" pos="0.011179904701333954 0 0" rgba="0.2 0.6 0.8 1"/>
                                              <site name="s1_19" pos="0.011179904701333954 0.01609906276992089 0" size="0.002" rgba="1 1 0 1"/>
                                              <site name="s2_19" pos="0.011179904701333954 -0.01609906276992089 0" size="0.002" rgba="1 1 0 1"/>
                                              <body name="seg_20" pos="0.022359809402667907 0 0" euler="0 0 -11.250000000000064">
                                                <joint name="j_20"/>
                                                <geom type="box" size="0.010749379537754788 0.012899255445305745 0.005" pos="0.010749379537754788 0 0" rgba="0.2 0.6 0.8 1"/>
                                                <site name="s1_20" pos="0.010749379537754788 0.015479106534366894 0" size="0.002" rgba="1 1 0 1"/>
                                                <site name="s2_20" pos="0.010749379537754788 -0.015479106534366894 0" size="0.002" rgba="1 1 0 1"/>
                                                <body name="seg_21" pos="0.021498759075509577 0 0" euler="0 0 -11.249999999999961">
                                                  <joint name="j_21"/>
                                                  <geom type="box" size="0.010335433398901327 0.012402520078681591 0.005" pos="0.010335433398901327 0 0" rgba="0.2 0.6 0.8 1"/>
                                                  <site name="s1_21" pos="0.010335433398901327 0.01488302409441791 0" size="0.002" rgba="1 1 0 1"/>
                                                  <site name="s2_21" pos="0.010335433398901327 -0.01488302409441791 0" size="0.002" rgba="1 1 0 1"/>
                                                  <body name="seg_22" pos="0.020670866797802653 0 0" euler="0 0 -11.249999999999899">
                                                    <joint name="j_22"/>
                                                    <geom type="box" size="0.009937427845759881 0.011924913414911857 0.005" pos="0.009937427845759881 0 0" rgba="0.2 0.6 0.8 1"/>
                                                    <site name="s1_22" pos="0.009937427845759881 0.014309896097894228 0" size="0.002" rgba="1 1 0 1"/>
                                                    <site name="s2_22" pos="0.009937427845759881 -0.014309896097894228 0" size="0.002" rgba="1 1 0 1"/>
                                                    <body name="seg_23" pos="0.019874855691519762 0 0" euler="0 0 -11.250000000000153">
                                                      <joint name="j_23"/>
                                                      <geom type="box" size="0.009554749024862474 0.01146569882983497 0.005" pos="0.009554749024862474 0 0" rgba="0.2 0.6 0.8 1"/>
                                                      <site name="s1_23" pos="0.009554749024862474 0.013758838595801964 0" size="0.002" rgba="1 1 0 1"/>
                                                      <site name="s2_23" pos="0.009554749024862474 -0.013758838595801964 0" size="0.002" rgba="1 1 0 1"/>
                                                      <body name="seg_24" pos="0.01910949804972495 0 0" euler="0 0 -11.249999999999911">
                                                        <joint name="j_24"/>
                                                        <geom type="box" size="0.009186806721526388 0.011024168065831666 0.005" pos="0.009186806721526388 0 0" rgba="0.2 0.6 0.8 1"/>
                                                        <site name="s1_24" pos="0.009186806721526388 0.013229001678997999 0" size="0.002" rgba="1 1 0 1"/>
                                                        <site name="s2_24" pos="0.009186806721526388 -0.013229001678997999 0" size="0.002" rgba="1 1 0 1"/>
                                                        <body name="seg_25" pos="0.018373613443052775 0 0" euler="0 0 -11.250000000000089">
                                                          <joint name="j_25"/>
                                                          <geom type="box" size="0.008833033449551775 0.01059964013946213 0.005" pos="0.008833033449551775 0 0" rgba="0.2 0.6 0.8 1"/>
                                                          <site name="s1_25" pos="0.008833033449551775 0.012719568167354556 0" size="0.002" rgba="1 1 0 1"/>
                                                          <site name="s2_25" pos="0.008833033449551775 -0.012719568167354556 0" size="0.002" rgba="1 1 0 1"/>
                                                          <body name="seg_26" pos="0.01766606689910355 0 0" euler="0 0 -11.249999999999892">
                                                            <joint name="j_26"/>
                                                            <geom type="box" size="0.008492883575974122 0.010191460291168946 0.005" pos="0.008492883575974122 0 0" rgba="0.2 0.6 0.8 1"/>
                                                            <site name="s1_26" pos="0.008492883575974122 0.012229752349402734 0" size="0.002" rgba="1 1 0 1"/>
                                                            <site name="s2_26" pos="0.008492883575974122 -0.012229752349402734 0" size="0.002" rgba="1 1 0 1"/>
                                                            <body name="seg_27" pos="0.016985767151948244 0 0" euler="0 0 -11.250000000000064">
                                                              <joint name="j_27"/>
                                                              <geom type="box" size="0.00816583247952172 0.009798998975426064 0.005" pos="0.00816583247952172 0 0" rgba="0.2 0.6 0.8 1"/>
                                                              <site name="s1_27" pos="0.00816583247952172 0.011758798770511277 0" size="0.002" rgba="1 1 0 1"/>
                                                              <site name="s2_27" pos="0.00816583247952172 -0.011758798770511277 0" size="0.002" rgba="1 1 0 1"/>
                                                              <body name="seg_28" pos="0.01633166495904344 0 0" euler="0 0 -11.25">
                                                                <joint name="j_28"/>
                                                                <geom type="box" size="0.007851375741479347 0.009421650889775217 0.005" pos="0.007851375741479347 0 0" rgba="0.2 0.6 0.8 1"/>
                                                                <site name="s1_28" pos="0.007851375741479347 0.01130598106773026 0" size="0.002" rgba="1 1 0 1"/>
                                                                <site name="s2_28" pos="0.007851375741479347 -0.01130598106773026 0" size="0.002" rgba="1 1 0 1"/>
                                                                <body name="seg_29" pos="0.015702751482958695 0 0" euler="0 0 -11.249999999999936">
                                                                  <joint name="j_29"/>
                                                                  <geom type="box" size="0.007549028367711576 0.009058834041253891 0.005" pos="0.007549028367711576 0 0" rgba="0.2 0.6 0.8 1"/>
                                                                  <site name="s1_29" pos="0.007549028367711576 0.010870600849504669 0" size="0.002" rgba="1 1 0 1"/>
                                                                  <site name="s2_29" pos="0.007549028367711576 -0.010870600849504669 0" size="0.002" rgba="1 1 0 1"/>
                                                                  <body name="seg_30" pos="0.015098056735423152 0 0" euler="0 0 -11.250000000000032">
                                                                    <joint name="j_30"/>
                                                                    <geom type="box" size="0.007258324040644766 0.00870998884877372 0.005" pos="0.007258324040644766 0 0" rgba="0.2 0.6 0.8 1"/>
                                                                    <site name="s1_30" pos="0.007258324040644766 0.010451986618528463 0" size="0.002" rgba="1 1 0 1"/>
                                                                    <site name="s2_30" pos="0.007258324040644766 -0.010451986618528463 0" size="0.002" rgba="1 1 0 1"/>
                                                                    <body name="seg_31" pos="0.014516648081289532 0 0" euler="0 0 -11.250000000000032">
                                                                      <joint name="j_31"/>
                                                                      <geom type="box" size="0.0069788144000539724 0.008374577280064766 0.005" pos="0.0069788144000539724 0 0" rgba="0.2 0.6 0.8 1"/>
                                                                      <site name="s1_31" pos="0.0069788144000539724 0.010049492736077718 0" size="0.002" rgba="1 1 0 1"/>
                                                                      <site name="s2_31" pos="0.0069788144000539724 -0.010049492736077718 0" size="0.002" rgba="1 1 0 1"/>
                                                                      <body name="seg_32" pos="0.013957628800107945 0 0" euler="0 0 -11.250000000000036">
                                                                        <joint name="j_32"/>
                                                                        <geom type="box" size="0.0067100683515466586 0.00805208202185599 0.005" pos="0.0067100683515466586 0 0" rgba="0.2 0.6 0.8 1"/>
                                                                        <site name="s1_32" pos="0.0067100683515466586 0.009662498426227187 0" size="0.002" rgba="1 1 0 1"/>
                                                                        <site name="s2_32" pos="0.0067100683515466586 -0.009662498426227187 0" size="0.002" rgba="1 1 0 1"/>
                                                                        <body name="seg_33" pos="0.013420136703093317 0 0" euler="0 0 -11.249999999999927">
                                                                          <joint name="j_33"/>
                                                                          <geom type="box" size="0.0064516714016753145 0.007742005682010377 0.005" pos="0.0064516714016753145 0 0" rgba="0.2 0.6 0.8 1"/>
                                                                          <site name="s1_33" pos="0.0064516714016753145 0.009290406818412452 0" size="0.002" rgba="1 1 0 1"/>
                                                                          <site name="s2_33" pos="0.0064516714016753145 -0.009290406818412452 0" size="0.002" rgba="1 1 0 1"/>
                                                                          <body name="seg_34" pos="0.012903342803350629 0 0" euler="0 0 -11.250000000000025">
                                                                            <joint name="j_34"/>
                                                                            <geom type="box" size="0.006203225018654344 0.007443870022385213 0.005" pos="0.006203225018654344 0 0" rgba="0.2 0.6 0.8 1"/>
                                                                            <site name="s1_34" pos="0.006203225018654344 0.008932644026862255 0" size="0.002" rgba="1 1 0 1"/>
                                                                            <site name="s2_34" pos="0.006203225018654344 -0.008932644026862255 0" size="0.002" rgba="1 1 0 1"/>
                                                                            <body name="seg_35" pos="0.012406450037308689 0 0" euler="0 0 -11.24999999999998">
                                                                              <joint name="j_35"/>
                                                                              <geom type="box" size="0.0059643460176950994 0.007157215221234119 0.005" pos="0.0059643460176950994 0 0" rgba="0.2 0.6 0.8 1"/>
                                                                              <site name="s1_35" pos="0.0059643460176950994 0.008588658265480944 0" size="0.002" rgba="1 1 0 1"/>
                                                                              <site name="s2_35" pos="0.0059643460176950994 -0.008588658265480944 0" size="0.002" rgba="1 1 0 1"/>
                                                                              <body name="seg_36" pos="0.011928692035390199 0 0" euler="0 0 -11.250000000000052">
                                                                                <joint name="j_36"/>
                                                                                <geom type="box" size="0.005734665970010571 0.006881599164012685 0.005" pos="0.005734665970010571 0 0" rgba="0.2 0.6 0.8 1"/>
                                                                                <site name="s1_36" pos="0.005734665970010571 0.008257918996815222 0" size="0.002" rgba="1 1 0 1"/>
                                                                                <site name="s2_36" pos="0.005734665970010571 -0.008257918996815222 0" size="0.002" rgba="1 1 0 1"/>
                                                                                <body name="seg_37" pos="0.011469331940021142 0 0" euler="0 0 -11.249999999999899">
                                                                                  <joint name="j_37"/>
                                                                                  <geom type="box" size="0.0055138306345791 0.00661659676149492 0.005" pos="0.0055138306345791 0 0" rgba="0.2 0.6 0.8 1"/>
                                                                                  <site name="s1_37" pos="0.0055138306345791 0.007939916113793903 0" size="0.002" rgba="1 1 0 1"/>
                                                                                  <site name="s2_37" pos="0.0055138306345791 -0.007939916113793903 0" size="0.002" rgba="1 1 0 1"/>
                                                                                  <body name="seg_38" pos="0.0110276612691582 0 0" euler="0 0 -11.250000000000089">
                                                                                    <joint name="j_38"/>
                                                                                    <geom type="box" size="0.005301499411790016 0.006361799294148019 0.005" pos="0.005301499411790016 0 0" rgba="0.2 0.6 0.8 1"/>
                                                                                    <site name="s1_38" pos="0.005301499411790016 0.0076341591529776225 0" size="0.002" rgba="1 1 0 1"/>
                                                                                    <site name="s2_38" pos="0.005301499411790016 -0.0076341591529776225 0" size="0.002" rgba="1 1 0 1"/>
                                                                                    <body name="seg_39" pos="0.010602998823580031 0 0" euler="0 0 -11.249999999999961">
                                                                                      <joint name="j_39"/>
                                                                                      <geom type="box" size="0.00509734481812846 0.006116813781754152 0.005" pos="0.00509734481812846 0 0" rgba="0.2 0.6 0.8 1"/>
                                                                                      <site name="s1_39" pos="0.00509734481812846 0.007340176538104983 0" size="0.002" rgba="1 1 0 1"/>
                                                                                      <site name="s2_39" pos="0.00509734481812846 -0.007340176538104983 0" size="0.002" rgba="1 1 0 1"/>
                                                                                    </body>
                                                                                  </body>
                                                                                </body>
                                                                              </body>
                                                                            </body>
                                                                          </body>
                                                                        </body>
                                                                      </body>
                                                                    </body>
                                                                  </body>
                                                                </body>
                                                              </body>
                                                            </body>
                                                          </body>
                                                        </body>
                                                      </body>
                                                    </body>
                                                  </body>
                                                </body>
                                              </body>
                                            </body>
                                          </body>
                                        </body>
                                      </body>
                                    </body>
                                  </body>
                                </body>
                              </body>
                            </body>
                          </body>
                        </body>
                      </body>
                    </body>
                  </body>
                </body>
              </body>
            </body>
          </body>
        </body>
      </body>
    </body>
  </worldbody>
  <tendon>
    <spatial name="cable_left" width="0.001" rgba="1 0 0 1">
      <site site="s1_0"/>
      <site site="s1_1"/>
      <site site="s1_2"/>
      <site site="s1_3"/>
      <site site="s1_4"/>
      <site site="s1_5"/>
      <site site="s1_6"/>
      <site site="s1_7"/>
      <site site="s1_8"/>
      <site site="s1_9"/>
      <site site="s1_10"/>
      <site site="s1_11"/>
      <site site="s1_12"/>
      <site site="s1_13"/>
      <site site="s1_14"/>
      <site site="s1_15"/>
      <site site="s1_16"/>
      <site site="s1_17"/>
      <site site="s1_18"/>
      <site site="s1_19"/>
      <site site="s1_20"/>
      <site site="s1_21"/>
      <site site="s1_22"/>
      <site site="s1_23"/>
      <site site="s1_24"/>
      <site site="s1_25"/>
      <site site="s1_26"/>
      <site site="s1_27"/>
      <site site="s1_28"/>
      <site site="s1_29"/>
      <site site="s1_30"/>
      <site site="s1_31"/>
      <site site="s1_32"/>
      <site site="s1_33"/>
      <site site="s1_34"/>
      <site site="s1_35"/>
      <site site="s1_36"/>
      <site site="s1_37"/>
      <site site="s1_38"/>
      <site site="s1_39"/>
    </spatial>
    <spatial name="cable_right" width="0.001" rgba="0 1 0 1">
      <site site="s2_0"/>
      <site site="s2_1"/>
      <site site="s2_2"/>
      <site site="s2_3"/>
      <site site="s2_4"/>
      <site site="s2_5"/>
      <site site="s2_6"/>
      <site site="s2_7"/>
      <site site="s2_8"/>
      <site site="s2_9"/>
      <site site="s2_10"/>
      <site site="s2_11"/>
      <site site="s2_12"/>
      <site site="s2_13"/>
      <site site="s2_14"/>
      <site site="s2_15"/>
      <site site="s2_16"/>
      <site site="s2_17"/>
      <site site="s2_18"/>
      <site site="s2_19"/>
      <site site="s2_20"/>
      <site site="s2_21"/>
      <site site="s2_22"/>
      <site site="s2_23"/>
      <site site="s2_24"/>
      <site site="s2_25"/>
      <site site="s2_26"/>
      <site site="s2_27"/>
      <site site="s2_28"/>
      <site site="s2_29"/>
      <site site="s2_30"/>
      <site site="s2_31"/>
      <site site="s2_32"/>
      <site site="s2_33"/>
      <site site="s2_34"/>
      <site site="s2_35"/>
      <site site="s2_36"/>
      <site site="s2_37"/>
      <site site="s2_38"/>
      <site site="s2_39"/>
    </spatial>
  </tendon>
  <actuator>
    <position name="act_left" tendon="cable_left" kp="20" kv="1" gear="1" ctrlrange="-0.3 0"/>
    <position name="act_right" tendon="cable_right" kp="20" kv="1" gear="1" ctrlrange="-0.3 0"/>
  </actuator>
</mujoco>
